[2023-12-04T17:02:53.169+0000] {taskinstance.py:1159} INFO - Dependencies all met for dep_context=non-requeueable deps ti=<TaskInstance: etl_local_to_gcs_to_bigquery.transforms_data.upload_transform_data_to_gcs manual__2023-12-04T17:02:43.073858+00:00 [queued]>
[2023-12-04T17:02:53.184+0000] {taskinstance.py:1159} INFO - Dependencies all met for dep_context=requeueable deps ti=<TaskInstance: etl_local_to_gcs_to_bigquery.transforms_data.upload_transform_data_to_gcs manual__2023-12-04T17:02:43.073858+00:00 [queued]>
[2023-12-04T17:02:53.185+0000] {taskinstance.py:1361} INFO - Starting attempt 1 of 1
[2023-12-04T17:02:53.209+0000] {taskinstance.py:1382} INFO - Executing <Task(LocalFilesystemToGCSOperator): transforms_data.upload_transform_data_to_gcs> on 2023-12-04 17:02:43.073858+00:00
[2023-12-04T17:02:53.220+0000] {standard_task_runner.py:57} INFO - Started process 84 to run task
[2023-12-04T17:02:53.227+0000] {standard_task_runner.py:84} INFO - Running: ['***', 'tasks', 'run', 'etl_local_to_gcs_to_bigquery', 'transforms_data.upload_transform_data_to_gcs', 'manual__2023-12-04T17:02:43.073858+00:00', '--job-id', '9', '--raw', '--subdir', 'DAGS_FOLDER/etl_gcs_to_bq.py', '--cfg-path', '/tmp/tmp920r90ou']
[2023-12-04T17:02:53.230+0000] {standard_task_runner.py:85} INFO - Job 9: Subtask transforms_data.upload_transform_data_to_gcs
[2023-12-04T17:02:53.309+0000] {task_command.py:416} INFO - Running <TaskInstance: etl_local_to_gcs_to_bigquery.transforms_data.upload_transform_data_to_gcs manual__2023-12-04T17:02:43.073858+00:00 [running]> on host 9ac898278c26
[2023-12-04T17:02:53.416+0000] {taskinstance.py:1662} INFO - Exporting env vars: AIRFLOW_CTX_DAG_OWNER='***' AIRFLOW_CTX_DAG_ID='etl_local_to_gcs_to_bigquery' AIRFLOW_CTX_TASK_ID='transforms_data.upload_transform_data_to_gcs' AIRFLOW_CTX_EXECUTION_DATE='2023-12-04T17:02:43.073858+00:00' AIRFLOW_CTX_TRY_NUMBER='1' AIRFLOW_CTX_DAG_RUN_ID='manual__2023-12-04T17:02:43.073858+00:00'
[2023-12-04T17:02:53.421+0000] {crypto.py:82} WARNING - empty cryptography key - values will not be stored encrypted.
[2023-12-04T17:02:53.426+0000] {connection.py:232} WARNING - Connection schemes (type: google_cloud_platform) shall not contain '_' according to RFC3986.
[2023-12-04T17:02:53.427+0000] {base.py:73} INFO - Using connection ID 'google_cloud_default' for task execution.
[2023-12-04T17:02:54.546+0000] {gcs.py:517} ERROR - Upload attempt of object: api_data_polusi_indonesia.parquet from api_data_polusi_indonesia.parquet has failed. Attempt: 1, max 1.
[2023-12-04T17:02:54.547+0000] {taskinstance.py:1937} ERROR - Task failed with exception
Traceback (most recent call last):
  File "/home/airflow/.local/lib/python3.8/site-packages/google/cloud/storage/blob.py", line 2604, in _prep_and_do_upload
    created_json = self._do_upload(
  File "/home/airflow/.local/lib/python3.8/site-packages/google/cloud/storage/blob.py", line 2410, in _do_upload
    response = self._do_multipart_upload(
  File "/home/airflow/.local/lib/python3.8/site-packages/google/cloud/storage/blob.py", line 1923, in _do_multipart_upload
    response = upload.transmit(
  File "/home/airflow/.local/lib/python3.8/site-packages/google/resumable_media/requests/upload.py", line 153, in transmit
    return _request_helpers.wait_and_retry(
  File "/home/airflow/.local/lib/python3.8/site-packages/google/resumable_media/requests/_request_helpers.py", line 155, in wait_and_retry
    response = func()
  File "/home/airflow/.local/lib/python3.8/site-packages/google/resumable_media/requests/upload.py", line 149, in retriable_request
    self._process_response(result)
  File "/home/airflow/.local/lib/python3.8/site-packages/google/resumable_media/_upload.py", line 125, in _process_response
    _helpers.require_status_code(response, (http.client.OK,), self._get_status_code)
  File "/home/airflow/.local/lib/python3.8/site-packages/google/resumable_media/_helpers.py", line 108, in require_status_code
    raise common.InvalidResponse(
google.resumable_media.common.InvalidResponse: ('Request failed with status code', 403, 'Expected one of', 200)

During handling of the above exception, another exception occurred:

Traceback (most recent call last):
  File "/home/airflow/.local/lib/python3.8/site-packages/airflow/providers/google/cloud/transfers/local_to_gcs.py", line 110, in execute
    hook.upload(
  File "/home/airflow/.local/lib/python3.8/site-packages/airflow/providers/google/cloud/hooks/gcs.py", line 556, in upload
    _call_with_retry(
  File "/home/airflow/.local/lib/python3.8/site-packages/airflow/providers/google/cloud/hooks/gcs.py", line 524, in _call_with_retry
    raise e
  File "/home/airflow/.local/lib/python3.8/site-packages/airflow/providers/google/cloud/hooks/gcs.py", line 514, in _call_with_retry
    f()
  File "/home/airflow/.local/lib/python3.8/site-packages/google/cloud/storage/blob.py", line 2926, in upload_from_filename
    self._handle_filename_and_upload(
  File "/home/airflow/.local/lib/python3.8/site-packages/google/cloud/storage/blob.py", line 2796, in _handle_filename_and_upload
    self._prep_and_do_upload(
  File "/home/airflow/.local/lib/python3.8/site-packages/google/cloud/storage/blob.py", line 2622, in _prep_and_do_upload
    _raise_from_invalid_response(exc)
  File "/home/airflow/.local/lib/python3.8/site-packages/google/cloud/storage/blob.py", line 4778, in _raise_from_invalid_response
    raise exceptions.from_http_status(response.status_code, message, response=response)
google.api_core.exceptions.Forbidden: 403 POST https://storage.googleapis.com/upload/storage/v1/b/ampun_puh_sepuh/o?uploadType=multipart: {
  "error": {
    "code": 403,
    "message": "airflow@msib-final-project.iam.gserviceaccount.com does not have storage.objects.delete access to the Google Cloud Storage object.",
    "errors": [
      {
        "message": "airflow@msib-final-project.iam.gserviceaccount.com does not have storage.objects.delete access to the Google Cloud Storage object.",
        "domain": "global",
        "reason": "forbidden"
      }
    ]
  }
}
: ('Request failed with status code', 403, 'Expected one of', <HTTPStatus.OK: 200>)
[2023-12-04T17:02:54.567+0000] {taskinstance.py:1400} INFO - Marking task as FAILED. dag_id=etl_local_to_gcs_to_bigquery, task_id=transforms_data.upload_transform_data_to_gcs, execution_date=20231204T170243, start_date=20231204T170253, end_date=20231204T170254
[2023-12-04T17:02:54.593+0000] {standard_task_runner.py:104} ERROR - Failed to execute job 9 for task transforms_data.upload_transform_data_to_gcs (403 POST https://storage.googleapis.com/upload/storage/v1/b/ampun_puh_sepuh/o?uploadType=multipart: {
  "error": {
    "code": 403,
    "message": "airflow@msib-final-project.iam.gserviceaccount.com does not have storage.objects.delete access to the Google Cloud Storage object.",
    "errors": [
      {
        "message": "airflow@msib-final-project.iam.gserviceaccount.com does not have storage.objects.delete access to the Google Cloud Storage object.",
        "domain": "global",
        "reason": "forbidden"
      }
    ]
  }
}
: ('Request failed with status code', 403, 'Expected one of', <HTTPStatus.OK: 200>); 84)
[2023-12-04T17:02:54.650+0000] {local_task_job_runner.py:228} INFO - Task exited with return code 1
[2023-12-04T17:02:54.681+0000] {taskinstance.py:2778} INFO - 0 downstream tasks scheduled from follow-on schedule check
