[2023-12-07T16:23:09.283+0000] {taskinstance.py:1159} INFO - Dependencies all met for dep_context=non-requeueable deps ti=<TaskInstance: etl_local_to_gcs_to_bigquery.loads_raw_data.upload_raw_data_2014_to_gcs manual__2023-12-07T16:23:04.448993+00:00 [queued]>
[2023-12-07T16:23:09.324+0000] {taskinstance.py:1159} INFO - Dependencies all met for dep_context=requeueable deps ti=<TaskInstance: etl_local_to_gcs_to_bigquery.loads_raw_data.upload_raw_data_2014_to_gcs manual__2023-12-07T16:23:04.448993+00:00 [queued]>
[2023-12-07T16:23:09.330+0000] {taskinstance.py:1361} INFO - Starting attempt 1 of 1
[2023-12-07T16:23:09.380+0000] {taskinstance.py:1382} INFO - Executing <Task(PythonOperator): loads_raw_data.upload_raw_data_2014_to_gcs> on 2023-12-07 16:23:04.448993+00:00
[2023-12-07T16:23:09.399+0000] {standard_task_runner.py:57} INFO - Started process 5456 to run task
[2023-12-07T16:23:09.521+0000] {standard_task_runner.py:84} INFO - Running: ['***', 'tasks', 'run', 'etl_local_to_gcs_to_bigquery', 'loads_raw_data.upload_raw_data_2014_to_gcs', 'manual__2023-12-07T16:23:04.448993+00:00', '--job-id', '156', '--raw', '--subdir', 'DAGS_FOLDER/etl_gcs_to_bq.py', '--cfg-path', '/tmp/tmp5hflh2_8']
[2023-12-07T16:23:09.537+0000] {standard_task_runner.py:85} INFO - Job 156: Subtask loads_raw_data.upload_raw_data_2014_to_gcs
[2023-12-07T16:23:09.854+0000] {task_command.py:416} INFO - Running <TaskInstance: etl_local_to_gcs_to_bigquery.loads_raw_data.upload_raw_data_2014_to_gcs manual__2023-12-07T16:23:04.448993+00:00 [running]> on host f19d185ad9e6
[2023-12-07T16:23:10.034+0000] {taskinstance.py:1662} INFO - Exporting env vars: AIRFLOW_CTX_DAG_OWNER='***' AIRFLOW_CTX_DAG_ID='etl_local_to_gcs_to_bigquery' AIRFLOW_CTX_TASK_ID='loads_raw_data.upload_raw_data_2014_to_gcs' AIRFLOW_CTX_EXECUTION_DATE='2023-12-07T16:23:04.448993+00:00' AIRFLOW_CTX_TRY_NUMBER='1' AIRFLOW_CTX_DAG_RUN_ID='manual__2023-12-07T16:23:04.448993+00:00'
[2023-12-07T16:23:10.037+0000] {taskinstance.py:1937} ERROR - Task failed with exception
Traceback (most recent call last):
  File "/home/airflow/.local/lib/python3.8/site-packages/airflow/operators/python.py", line 192, in execute
    return_value = self.execute_callable()
  File "/home/airflow/.local/lib/python3.8/site-packages/airflow/operators/python.py", line 209, in execute_callable
    return self.python_callable(*self.op_args, **self.op_kwargs)
  File "/opt/airflow/dags/etl_gcs_to_bq.py", line 364, in upload_raw_2014_to_gcs
    upload_task = LocalFilesystemToGCSOperator(
  File "/home/airflow/.local/lib/python3.8/site-packages/airflow/models/baseoperator.py", line 437, in apply_defaults
    result = func(self, **kwargs, default_args=default_args)
  File "/home/airflow/.local/lib/python3.8/site-packages/airflow/providers/google/cloud/transfers/local_to_gcs.py", line 78, in __init__
    super().__init__(**kwargs)
  File "/home/airflow/.local/lib/python3.8/site-packages/airflow/models/baseoperator.py", line 437, in apply_defaults
    result = func(self, **kwargs, default_args=default_args)
TypeError: __init__() missing 1 required positional argument: 'task_id'
[2023-12-07T16:23:10.072+0000] {taskinstance.py:1400} INFO - Marking task as FAILED. dag_id=etl_local_to_gcs_to_bigquery, task_id=loads_raw_data.upload_raw_data_2014_to_gcs, execution_date=20231207T162304, start_date=20231207T162309, end_date=20231207T162310
[2023-12-07T16:23:10.099+0000] {standard_task_runner.py:104} ERROR - Failed to execute job 156 for task loads_raw_data.upload_raw_data_2014_to_gcs (__init__() missing 1 required positional argument: 'task_id'; 5456)
[2023-12-07T16:23:10.154+0000] {local_task_job_runner.py:228} INFO - Task exited with return code 1
[2023-12-07T16:23:10.194+0000] {taskinstance.py:2778} INFO - 0 downstream tasks scheduled from follow-on schedule check
