[2023-12-11T12:49:14.639+0000] {taskinstance.py:1159} INFO - Dependencies all met for dep_context=non-requeueable deps ti=<TaskInstance: etl_local_to_gcs_to_bigquery_api.upload_transform_data_to_gcs scheduled__2023-12-10T00:00:00+00:00 [queued]>
[2023-12-11T12:49:14.660+0000] {taskinstance.py:1159} INFO - Dependencies all met for dep_context=requeueable deps ti=<TaskInstance: etl_local_to_gcs_to_bigquery_api.upload_transform_data_to_gcs scheduled__2023-12-10T00:00:00+00:00 [queued]>
[2023-12-11T12:49:14.661+0000] {taskinstance.py:1361} INFO - Starting attempt 8 of 8
[2023-12-11T12:49:14.691+0000] {taskinstance.py:1382} INFO - Executing <Task(LocalFilesystemToGCSOperator): upload_transform_data_to_gcs> on 2023-12-10 00:00:00+00:00
[2023-12-11T12:49:14.704+0000] {standard_task_runner.py:57} INFO - Started process 91 to run task
[2023-12-11T12:49:14.713+0000] {standard_task_runner.py:84} INFO - Running: ['***', 'tasks', 'run', 'etl_local_to_gcs_to_bigquery_api', 'upload_transform_data_to_gcs', 'scheduled__2023-12-10T00:00:00+00:00', '--job-id', '279', '--raw', '--subdir', 'DAGS_FOLDER/etl_gcs_to_bq_api.py', '--cfg-path', '/tmp/tmp_of9f_s2']
[2023-12-11T12:49:14.720+0000] {standard_task_runner.py:85} INFO - Job 279: Subtask upload_transform_data_to_gcs
[2023-12-11T12:49:14.808+0000] {task_command.py:416} INFO - Running <TaskInstance: etl_local_to_gcs_to_bigquery_api.upload_transform_data_to_gcs scheduled__2023-12-10T00:00:00+00:00 [running]> on host c0a30b49a736
[2023-12-11T12:49:14.953+0000] {taskinstance.py:1662} INFO - Exporting env vars: AIRFLOW_CTX_DAG_EMAIL='driansptra21@gmail.com,massamunekun21@gmail.com' AIRFLOW_CTX_DAG_OWNER='***' AIRFLOW_CTX_DAG_ID='etl_local_to_gcs_to_bigquery_api' AIRFLOW_CTX_TASK_ID='upload_transform_data_to_gcs' AIRFLOW_CTX_EXECUTION_DATE='2023-12-10T00:00:00+00:00' AIRFLOW_CTX_TRY_NUMBER='8' AIRFLOW_CTX_DAG_RUN_ID='scheduled__2023-12-10T00:00:00+00:00'
[2023-12-11T12:49:14.959+0000] {crypto.py:82} WARNING - empty cryptography key - values will not be stored encrypted.
[2023-12-11T12:49:14.962+0000] {connection.py:232} WARNING - Connection schemes (type: google_cloud_platform) shall not contain '_' according to RFC3986.
[2023-12-11T12:49:14.966+0000] {base.py:73} INFO - Using connection ID 'google_cloud_default' for task execution.
[2023-12-11T12:49:14.968+0000] {taskinstance.py:1937} ERROR - Task failed with exception
Traceback (most recent call last):
  File "/home/airflow/.local/lib/python3.8/site-packages/airflow/providers/google/cloud/transfers/local_to_gcs.py", line 97, in execute
    raise FileNotFoundError(self.src)
FileNotFoundError: /opt/***/dataset/transform/api_data_polusi_indonesia
[2023-12-11T12:49:14.987+0000] {taskinstance.py:1400} INFO - Marking task as FAILED. dag_id=etl_local_to_gcs_to_bigquery_api, task_id=upload_transform_data_to_gcs, execution_date=20231210T000000, start_date=20231211T124914, end_date=20231211T124914
[2023-12-11T12:49:15.025+0000] {warnings.py:109} WARNING - /home/***/.local/lib/python3.8/site-packages/***/utils/email.py:154: RemovedInAirflow3Warning: Fetching SMTP credentials from configuration variables will be deprecated in a future release. Please set credentials using a connection instead.
  send_mime_email(e_from=mail_from, e_to=recipients, mime_msg=msg, conn_id=conn_id, dryrun=dryrun)

[2023-12-11T12:49:15.028+0000] {configuration.py:1050} WARNING - section/key [smtp/smtp_user] not found in config
[2023-12-11T12:49:15.033+0000] {email.py:270} INFO - Email alerting: attempt 1
[2023-12-11T12:49:15.051+0000] {configuration.py:1050} WARNING - section/key [smtp/smtp_user] not found in config
[2023-12-11T12:49:15.053+0000] {email.py:270} INFO - Email alerting: attempt 1
[2023-12-11T12:49:15.061+0000] {taskinstance.py:2007} ERROR - Failed to send email to: ['driansptra21@gmail.com', 'massamunekun21@gmail.com']
Traceback (most recent call last):
  File "/home/airflow/.local/lib/python3.8/site-packages/airflow/models/taskinstance.py", line 1518, in _run_raw_task
    self._execute_task_with_callbacks(context, test_mode, session=session)
  File "/home/airflow/.local/lib/python3.8/site-packages/airflow/models/taskinstance.py", line 1681, in _execute_task_with_callbacks
    result = self._execute_task(context, task_orig)
  File "/home/airflow/.local/lib/python3.8/site-packages/airflow/models/taskinstance.py", line 1744, in _execute_task
    result = execute_callable(context=context, **execute_callable_kwargs)
  File "/home/airflow/.local/lib/python3.8/site-packages/airflow/providers/google/cloud/transfers/local_to_gcs.py", line 97, in execute
    raise FileNotFoundError(self.src)
FileNotFoundError: /opt/***/dataset/transform/api_data_polusi_indonesia

During handling of the above exception, another exception occurred:

Traceback (most recent call last):
  File "/home/airflow/.local/lib/python3.8/site-packages/airflow/models/taskinstance.py", line 2420, in email_alert
    send_email(task.email, subject, html_content)
  File "/home/airflow/.local/lib/python3.8/site-packages/airflow/utils/email.py", line 80, in send_email
    return backend(
  File "/home/airflow/.local/lib/python3.8/site-packages/airflow/utils/email.py", line 154, in send_email_smtp
    send_mime_email(e_from=mail_from, e_to=recipients, mime_msg=msg, conn_id=conn_id, dryrun=dryrun)
  File "/home/airflow/.local/lib/python3.8/site-packages/airflow/utils/email.py", line 272, in send_mime_email
    smtp_conn = _get_smtp_connection(smtp_host, smtp_port, smtp_timeout, smtp_ssl)
  File "/home/airflow/.local/lib/python3.8/site-packages/airflow/utils/email.py", line 316, in _get_smtp_connection
    return smtplib.SMTP(host=host, port=port, timeout=timeout)
  File "/usr/local/lib/python3.8/smtplib.py", line 255, in __init__
    (code, msg) = self.connect(host, port)
  File "/usr/local/lib/python3.8/smtplib.py", line 339, in connect
    self.sock = self._get_socket(host, port, self.timeout)
  File "/usr/local/lib/python3.8/smtplib.py", line 310, in _get_socket
    return socket.create_connection((host, port), timeout,
  File "/usr/local/lib/python3.8/socket.py", line 808, in create_connection
    raise err
  File "/usr/local/lib/python3.8/socket.py", line 796, in create_connection
    sock.connect(sa)
OSError: [Errno 99] Cannot assign requested address

During handling of the above exception, another exception occurred:

Traceback (most recent call last):
  File "/home/airflow/.local/lib/python3.8/site-packages/airflow/models/taskinstance.py", line 2005, in handle_failure
    self.email_alert(error, task)
  File "/home/airflow/.local/lib/python3.8/site-packages/airflow/models/taskinstance.py", line 2422, in email_alert
    send_email(task.email, subject, html_content_err)
  File "/home/airflow/.local/lib/python3.8/site-packages/airflow/utils/email.py", line 80, in send_email
    return backend(
  File "/home/airflow/.local/lib/python3.8/site-packages/airflow/utils/email.py", line 154, in send_email_smtp
    send_mime_email(e_from=mail_from, e_to=recipients, mime_msg=msg, conn_id=conn_id, dryrun=dryrun)
  File "/home/airflow/.local/lib/python3.8/site-packages/airflow/utils/email.py", line 272, in send_mime_email
    smtp_conn = _get_smtp_connection(smtp_host, smtp_port, smtp_timeout, smtp_ssl)
  File "/home/airflow/.local/lib/python3.8/site-packages/airflow/utils/email.py", line 316, in _get_smtp_connection
    return smtplib.SMTP(host=host, port=port, timeout=timeout)
  File "/usr/local/lib/python3.8/smtplib.py", line 255, in __init__
    (code, msg) = self.connect(host, port)
  File "/usr/local/lib/python3.8/smtplib.py", line 339, in connect
    self.sock = self._get_socket(host, port, self.timeout)
  File "/usr/local/lib/python3.8/smtplib.py", line 310, in _get_socket
    return socket.create_connection((host, port), timeout,
  File "/usr/local/lib/python3.8/socket.py", line 808, in create_connection
    raise err
  File "/usr/local/lib/python3.8/socket.py", line 796, in create_connection
    sock.connect(sa)
OSError: [Errno 99] Cannot assign requested address
[2023-12-11T12:49:15.102+0000] {standard_task_runner.py:104} ERROR - Failed to execute job 279 for task upload_transform_data_to_gcs (/opt/***/dataset/transform/api_data_polusi_indonesia; 91)
[2023-12-11T12:49:15.166+0000] {local_task_job_runner.py:228} INFO - Task exited with return code 1
[2023-12-11T12:49:15.220+0000] {taskinstance.py:2778} INFO - 0 downstream tasks scheduled from follow-on schedule check
